Workbook

Sheet All_India_Index_Upto_April23 (1
A1: Sector | B1: Year | C1: Month | D1: Cereals and products | E1: Meat and fish | F1: Egg | G1: Milk and products | H1: Oils and fats | I1: Fruits | J1: Vegetables | K1: Pulses and products | L1: Sugar and Confectionery | M1: Spices | N1: Non-alcoholic beverages | O1: Prepared meals, snacks, sweets etc. | P1: Food and beverages | Q1: Pan, tobacco and intoxicants | R1: Clothing | S1: Footwear | T1: Clothing and footwear | U1: Housing | V1: Fuel and light | W1: Household goods and services | X1: Health | Y1: Transport and communication | Z1: Recreation and amusement | AA1: Education | AB1: Personal care and effects | AC1: Miscellaneous | AD1: General index
A2: Rural | B2: 2013 | C2: January | D2: 107.5 | E2: 106.3 | F2: 108.1 | G2: 104.9 | H2: 106.1 | I2: 103.9 | J2: 101.9 | K2: 106.1 | L2: 106.8 | M2: 103.1 | N2: 104.8 | O2: 106.7 | P2: 105.5 | Q2: 105.1 | R2: 106.5 | S2: 105.8 | T2: 106.4 | U2: NA | V2: 105.5 | W2: 104.8 | X2: 104 | Y2: 103.3 | Z2: 103.4 | AA2: 103.8 | AB2: 104.7 | AC2: 104 | AD2: 105.1
A3: Urban | B3: 2013 | C3: January | D3: 110.5 | E3: 109.1 | F3: 113 | G3: 103.6 | H3: 103.4 | I3: 102.3 | J3: 102.9 | K3: 105.8 | L3: 105.1 | M3: 101.8 | N3: 105.1 | O3: 107.9 | P3: 105.9 | Q3: 105.2 | R3: 105.9 | S3: 105 | T3: 105.8 | U3: 100.3 | V3: 105.4 | W3: 104.8 | X3: 104.1 | Y3: 103.2 | Z3: 102.9 | AA3: 103.5 | AB3: 104.3 | AC3: 103.7 | AD3: 104
A4: Rural+Urban | B4: 2013 | C4: January | D4: 108.4 | E4: 107.3 | F4: 110 | G4: 104.4 | H4: 105.1 | I4: 103.2 | J4: 102.2 | K4: 106 | L4: 106.2 | M4: 102.7 | N4: 104.9 | O4: 107.3 | P4: 105.6 | Q4: 105.1 | R4: 106.3 | S4: 105.5 | T4: 106.2 | U4: 100.3 | V4: 105.5 | W4: 104.8 | X4: 104 | Y4: 103.2 | Z4: 103.1 | AA4: 103.6 | AB4: 104.5 | AC4: 103.9 | AD4: 104.6
A5: Rural | B5: 2013 | C5: February | D5: 109.2 | E5: 108.7 | F5: 110.2 | G5: 105.4 | H5: 106.7 | I5: 104 | J5: 102.4 | K5: 105.9 | L5: 105.7 | M5: 103.1 | N5: 105.1 | O5: 107.7 | P5: 106.3 | Q5: 105.6 | R5: 107.1 | S5: 106.3 | T5: 107 | U5: NA | V5: 106.2 | W5: 105.2 | X5: 104.4 | Y5: 103.9 | Z5: 104 | AA5: 104.1 | AB5: 104.6 | AC5: 104.4 | AD5: 105.8
A6: Urban | B6: 2013 | C6: February | D6: 112.9 | E6: 112.9 | F6: 116.9 | G6: 104 | H6: 103.5 | I6: 103.1 | J6: 104.9 | K6: 104.1 | L6: 103.8 | M6: 102.3 | N6: 106 | O6: 109 | P6: 107.2 | Q6: 106 | R6: 106.6 | S6: 105.5 | T6: 106.4 | U6: 100.4 | V6: 105.7 | W6: 105.2 | X6: 104.7 | Y6: 104.4 | Z6: 103.3 | AA6: 103.7 | AB6: 104.3 | AC6: 104.3 | AD6: 104.7
A7: Rural+Urban | B7: 2013 | C7: February | D7: 110.4 | E7: 110.2 | F7: 112.8 | G7: 104.9 | H7: 105.5 | I7: 103.6 | J7: 103.2 | K7: 105.3 | L7: 105.1 | M7: 102.8 | N7: 105.5 | O7: 108.3 | P7: 106.6 | Q7: 105.7 | R7: 106.9 | S7: 106 | T7: 106.8 | U7: 100.4 | V7: 106 | W7: 105.2 | X7: 104.5 | Y7: 104.2 | Z7: 103.6 | AA7: 103.9 | AB7: 104.5 | AC7: 104.4 | AD7: 105.3
A8: Rural | B8: 2013 | C8: March | D8: 110.2 | E8: 108.8 | F8: 109.9 | G8: 105.6 | H8: 106.2 | I8: 105.7 | J8: 101.4 | K8: 105.7 | L8: 105 | M8: 103.3 | N8: 105.6 | O8: 108.2 | P8: 106.6 | Q8: 106.5 | R8: 107.6 | S8: 106.8 | T8: 107.5 | U8: NA | V8: 106.1 | W8: 105.6 | X8: 104.7 | Y8: 104.6 | Z8: 104 | AA8: 104.3 | AB8: 104.3 | AC8: 104.6 | AD8: 106
A9: Urban | B9: 2013 | C9: March | D9: 113.9 | E9: 111.4 | F9: 113.2 | G9: 104.3 | H9: 102.7 | I9: 104.9 | J9: 103.8 | K9: 103.5 | L9: 102.6 | M9: 102.4 | N9: 107 | O9: 109.8 | P9: 107.3 | Q9: 106.8 | R9: 107.2 | S9: 106 | T9: 107 | U9: 100.4 | V9: 106 | W9: 105.7 | X9: 105.2 | Y9: 105.5 | Z9: 103.5 | AA9: 103.8 | AB9: 104.2 | AC9: 104.9 | AD9: 105
A10: Rural+Urban | B10: 2013 | C10: March | D10: 111.4 | E10: 109.7 | F10: 111.2 | G10: 105.1 | H10: 104.9 | I10: 105.3 | J10: 102.2 | K10: 105 | L10: 104.2 | M10: 103 | N10: 106.2 | O10: 108.9 | P10: 106.9 | Q10: 106.6 | R10: 107.4 | S10: 106.5 | T10: 107.3 | U10: 100.4 | V10: 106.1 | W10: 105.6 | X10: 104.9 | Y10: 105.1 | Z10: 103.7 | AA10: 104 | AB10: 104.3 | AC10: 104.7 | AD10: 105.5
A11: Rural | B11: 2013 | C11: April | D11: 110.2 | E11: 109.5 | F11: 106.9 | G11: 106.3 | H11: 105.7 | I11: 108.3 | J11: 103.4 | K11: 105.7 | L11: 104.2 | M11: 103.2 | N11: 106.5 | O11: 108.8 | P11: 107.1 | Q11: 107.1 | R11: 108.1 | S11: 107.4 | T11: 108 | U11: NA | V11: 106.5 | W11: 106.1 | X11: 105.1 | Y11: 104.4 | Z11: 104.5 | AA11: 104.8 | AB11: 102.7 | AC11: 104.6 | AD11: 106.4
A12: Urban | B12: 2013 | C12: April | D12: 114.6 | E12: 113.4 | F12: 106 | G12: 104.7 | H12: 102.1 | I12: 109.5 | J12: 109.7 | K12: 104.6 | L12: 102 | M12: 103.5 | N12: 108.2 | O12: 110.6 | P12: 108.8 | Q12: 108.5 | R12: 107.9 | S12: 106.4 | T12: 107.7 | U12: 100.5 | V12: 106.4 | W12: 106.5 | X12: 105.7 | Y12: 105 | Z12: 104 | AA12: 105.2 | AB12: 103.2 | AC12: 105.1 | AD12: 105.7
A13: Rural+Urban | B13: 2013 | C13: April | D13: 111.6 | E13: 110.9 | F13: 106.6 | G13: 105.7 | H13: 104.4 | I13: 108.9 | J13: 105.5 | K13: 105.3 | L13: 103.5 | M13: 103.3 | N13: 107.2 | O13: 109.6 | P13: 107.7 | Q13: 107.5 | R13: 108 | S13: 107 | T13: 107.9 | U13: 100.5 | V13: 106.5 | W13: 106.3 | X13: 105.3 | Y13: 104.7 | Z13: 104.2 | AA13: 105 | AB13: 102.9 | AC13: 104.8 | AD13: 106.1
A14: Rural | B14: 2013 | C14: May | D14: 110.9 | E14: 109.8 | F14: 105.9 | G14: 107.5 | H14: 105.3 | I14: 108.1 | J14: 107.3 | K14: 106.1 | L14: 103.7 | M14: 104 | N14: 107.4 | O14: 109.9 | P14: 108.1 | Q14: 108.1 | R14: 108.8 | S14: 107.9 | T14: 108.6 | U14: NA | V14: 107.5 | W14: 106.8 | X14: 105.7 | Y14: 104.1 | Z14: 105 | AA14: 105.5 | AB14: 102.1 | AC14: 104.8 | AD14: 107.2
A15: Urban | B15: 2013 | C15: May | D15: 115.4 | E15: 114.2 | F15: 102.7 | G15: 105.5 | H15: 101.5 | I15: 110.6 | J15: 123.7 | K15: 105.2 | L15: 101.9 | M15: 105 | N15: 109.1 | O15: 111.3 | P15: 111.1 | Q15: 109.8 | R15: 108.5 | S15: 106.7 | T15: 108.3 | U15: 100.5 | V15: 107.2 | W15: 107.1 | X15: 106.2 | Y15: 103.9 | Z15: 104.6 | AA15: 105.7 | AB15: 102.6 | AC15: 104.9 | AD15: 106.6
A16: Rural+Urban | B16: 2013 | C16: May | D16: 112.3 | E16: 111.3 | F16: 104.7 | G16: 106.8 | H16: 103.9 | I16: 109.3 | J16: 112.9 | K16: 105.8 | L16: 103.1 | M16: 104.3 | N16: 108.1 | O16: 110.5 | P16: 109.2 | Q16: 108.6 | R16: 108.7 | S16: 107.4 | T16: 108.5 | U16: 100.5 | V16: 107.4 | W16: 106.9 | X16: 105.9 | Y16: 104 | Z16: 104.8 | AA16: 105.6 | AB16: 102.3 | AC16: 104.8 | AD16: 106.9
A17: Rural | B17: 2013 | C17: June | D17: 112.3 | E17: 112.1 | F17: 108.1 | G17: 108.3 | H17: 105.9 | I17: 109.2 | J17: 118 | K17: 106.8 | L17: 104.1 | M17: 105.4 | N17: 108.2 | O17: 111 | P17: 110.6 | Q17: 109 | R17: 109.7 | S17: 108.8 | T17: 109.5 | U17: NA | V17: 108.5 | W17: 107.5 | X17: 106.3 | Y17: 105 | Z17: 105.6 | AA17: 106.5 | AB17: 102.5 | AC17: 105.5 | AD17: 108.9
A18: Urban | B18: 2013 | C18: June | D18: 117 | E18: 120.1 | F18: 112.5 | G18: 107.3 | H18: 101.3 | I18: 112.4 | J18: 143.6 | K18: 105.4 | L18: 101.4 | M18: 106.4 | N18: 110 | O18: 112.2 | P18: 115 | Q18: 110.9 | R18: 109.2 | S18: 107.2 | T18: 108.9 | U18: 106.6 | V18: 108 | W18: 107.7 | X18: 106.5 | Y18: 105.2 | Z18: 105.2 | AA18: 108.1 | AB18: 103.3 | AC18: 106.1 | AD18: 109.7
A19: Rural+Urban | B19: 2013 | C19: June | D19: 113.8 | E19: 114.9 | F19: 109.8 | G19: 107.9 | H19: 104.2 | I19: 110.7 | J19: 126.7 | K19: 106.3 | L19: 103.2 | M19: 105.7 | N19: 109 | O19: 111.6 | P19: 112.2 | Q19: 109.5 | R19: 109.5 | S19: 108.1 | T19: 109.3 | U19: 106.6 | V19: 108.3 | W19: 107.6 | X19: 106.4 | Y19: 105.1 | Z19: 105.4 | AA19: 107.4 | AB19: 102.8 | AC19: 105.8 | AD19: 109.3
A20: Rural | B20: 2013 | C20: July | D20: 113.4 | E20: 114.9 | F20: 110.5 | G20: 109.3 | H20: 106.2 | I20: 110.3 | J20: 129.2 | K20: 107.1 | L20: 104.3 | M20: 106.4 | N20: 109.1 | O20: 112.1 | P20: 113.1 | Q20: 109.8 | R20: 110.5 | S20: 109.5 | T20: 110.3 | U20: NA | V20: 109.5 | W20: 108.3 | X20: 106.9 | Y20: 106.8 | Z20: 106.4 | AA20: 107.8 | AB20: 102.5 | AC20: 106.5 | AD20: 110.7
A21: Urban | B21: 2013 | C21: July | D21: 117.8 | E21: 119.2 | F21: 114 | G21: 108.3 | H21: 101.1 | I21: 113.2 | J21: 160.9 | K21: 105.1 | L21: 101.3 | M21: 107.5 | N21: 110.4 | O21: 113.1 | P21: 117.5 | Q21: 111.7 | R21: 109.8 | S21: 107.8 | T21: 109.5 | U21: 107.7 | V21: 108.6 | W21: 108.1 | X21: 107.1 | Y21: 107.3 | Z21: 105.9 | AA21: 110.1 | AB21: 103.2 | AC21: 107.3 | AD21: 111.4
A22: Rural+Urban | B22: 2013 | C22: July | D22: 114.8 | E22: 116.4 | F22: 111.9 | G22: 108.9 | H22: 104.3 | I22: 111.7 | J22: 140 | K22: 106.4 | L22: 103.3 | M22: 106.8 | N22: 109.6 | O22: 112.6 | P22: 114.7 | Q22: 110.3 | R22: 110.2 | S22: 108.8 | T22: 110 | U22: 107.7 | V22: 109.2 | W22: 108.2 | X22: 107 | Y22: 107.1 | Z22: 106.1 | AA22: 109.1 | AB22: 102.8 | AC22: 106.9 | AD22: 111
A23: Rural | B23: 2013 | C23: August | D23: 114.3 | E23: 115.4 | F23: 111.1 | G23: 110 | H23: 106.4 | I23: 110.8 | J23: 138.9 | K23: 107.4 | L23: 104.1 | M23: 106.9 | N23: 109.7 | O23: 112.6 | P23: 114.9 | Q23: 110.7 | R23: 111.3 | S23: 110.2 | T23: 111.1 | U23: NA | V23: 109.9 | W23: 108.7 | X23: 107.5 | Y23: 107.8 | Z23: 106.8 | AA23: 108.7 | AB23: 105 | AC23: 107.5 | AD23: 112.1
A24: Urban | B24: 2013 | C24: August | D24: 118.3 | E24: 120.4 | F24: 112.7 | G24: 108.9 | H24: 101.1 | I24: 108.7 | J24: 177 | K24: 104.7 | L24: 101 | M24: 108.5 | N24: 110.9 | O24: 114.3 | P24: 119.6 | Q24: 112.4 | R24: 110.6 | S24: 108.3 | T24: 110.2 | U24: 108.9 | V24: 109.3 | W24: 108.7 | X24: 107.6 | Y24: 108.1 | Z24: 106.5 | AA24: 110.8 | AB24: 106 | AC24: 108.3 | AD24: 112.7
A25: Rural+Urban | B25: 2013 | C25: August | D25: 115.6 | E25: 117.2 | F25: 111.7 | G25: 109.6 | H25: 104.5 | I25: 109.8 | J25: 151.8 | K25: 106.5 | L25: 103.1 | M25: 107.4 | N25: 110.2 | O25: 113.4 | P25: 116.6 | Q25: 111.2 | R25: 111 | S25: 109.4 | T25: 110.7 | U25: 108.9 | V25: 109.7 | W25: 108.7 | X25: 107.5 | Y25: 108 | Z25: 106.6 | AA25: 109.9 | AB25: 105.4 | AC25: 107.9 | AD25: 112.4
A26: Rural | B26: 2013 | C26: September | D26: 115.4 | E26: 115.7 | F26: 111.7 | G26: 111 | H26: 107.4 | I26: 110.9 | J26: 154 | K26: 108.1 | L26: 104.2 | M26: 107.9 | N26: 110.4 | O26: 114 | P26: 117.8 | Q26: 111.7 | R26: 112.7 | S26: 111.4 | T26: 112.5 | U26: NA | V26: 111.1 | W26: 109.6 | X26: 108.3 | Y26: 109.3 | Z26: 107.7 | AA26: 109.8 | AB26: 106.7 | AC26: 108.7 | AD26: 114.2
A27: Urban | B27: 2013 | C27: September | D27: 118.6 | E27: 119.1 | F27: 113.2 | G27: 109.6 | H27: 101.7 | I27: 103.2 | J27: 174.3 | K27: 105.1 | L27: 100.8 | M27: 109.1 | N27: 111.1 | O27: 115.4 | P27: 119.2 | Q27: 112.9 | R27: 111.4 | S27: 109 | T27: 111.1 | U27: 109.7 | V27: 109.5 | W27: 109.6 | X27: 107.9 | Y27: 110.4 | Z27: 107.4 | AA27: 111.2 | AB27: 106.9 | AC27: 109.4 | AD27: 113.2
A28: Rural+Urban | B28: 2013 | C28: September | D28: 116.4 | E28: 116.9 | F28: 112.3 | G28: 110.5 | H28: 105.3 | I28: 107.3 | J28: 160.9 | K28: 107.1 | L28: 103.1 | M28: 108.3 | N28: 110.7 | O28: 114.6 | P28: 118.3 | Q28: 112 | R28: 112.2 | S28: 110.4 | T28: 111.9 | U28: 109.7 | V28: 110.5 | W28: 109.6 | X28: 108.1 | Y28: 109.9 | Z28: 107.5 | AA28: 110.6 | AB28: 106.8 | AC28: 109 | AD28: 113.7
A29: Rural | B29: 2013 | C29: October | D29: 116.3 | E29: 115.4 | F29: 112.6 | G29: 111.7 | H29: 107.7 | I29: 113.2 | J29: 164.9 | K29: 108.3 | L29: 103.9 | M29: 108.2 | N29: 111.1 | O29: 114.9 | P29: 119.8 | Q29: 112.2 | R29: 113.6 | S29: 112.3 | T29: 113.4 | U29: NA | V29: 111.6 | W29: 110.4 | X29: 108.9 | Y29: 109.3 | Z29: 108.3 | AA29: 110.2 | AB29: 107.5 | AC29: 109.1 | AD29: 115.5
A30: Urban | B30: 2013 | C30: October | D30: 118.9 | E30: 118.1 | F30: 114.5 | G30: 110.4 | H30: 102.3 | I30: 106.2 | J30: 183.5 | K30: 105.3 | L30: 100.2 | M30: 109.6 | N30: 111.4 | O30: 116 | P30: 120.8 | Q30: 113.5 | R30: 112.5 | S30: 109.7 | T30: 112 | U30: 110.5 | V30: 109.7 | W30: 110.2 | X30: 108.2 | Y30: 109.7 | Z30: 108 | AA30: 111.3 | AB30: 107.3 | AC30: 109.4 | AD30: 114
A31: Rural+Urban | B31: 2013 | C31: October | D31: 117.1 | E31: 116.3 | F31: 113.3 | G31: 111.2 | H31: 105.7 | I31: 109.9 | J31: 171.2 | K31: 107.3 | L31: 102.7 | M31: 108.7 | N31: 111.2 | O31: 115.4 | P31: 120.2 | Q31: 112.5 | R31: 113.2 | S31: 111.2 | T31: 112.8 | U31: 110.5 | V31: 110.9 | W31: 110.3 | X31: 108.6 | Y31: 109.5 | Z31: 108.1 | AA31: 110.8 | AB31: 107.4 | AC31: 109.2 | AD31: 114.8
A32: Rural | B32: 2013 | C32: November | D32: 117.3 | E32: 114.9 | F32: 116.2 | G32: 112.8 | H32: 108.9 | I32: 116.6 | J32: 178.1 | K32: 109.1 | L32: 103.6 | M32: 109 | N32: 111.8 | O32: 116 | P32: 122.5 | Q32: 112.8 | R32: 114.6 | S32: 113.1 | T32: 114.4 | U32: NA | V32: 112.6 | W32: 111.3 | X32: 109.7 | Y32: 109.6 | Z32: 108.7 | AA32: 111 | AB32: 108.2 | AC32: 109.8 | AD32: 117.4
A33: Urban | B33: 2013 | C33: November | D33: 119.8 | E33: 116.3 | F33: 122.6 | G33: 112 | H33: 103.2 | I33: 110 | J33: 192.8 | K33: 106.3 | L33: 99.5 | M33: 110.3 | N33: 111.8 | O33: 117.1 | P33: 122.9 | Q33: 114.1 | R33: 113.5 | S33: 110.3 | T33: 113 | U33: 111.1 | V33: 110 | W33: 110.9 | X33: 108.6 | Y33: 109.5 | Z33: 108.5 | AA33: 111.3 | AB33: 107.9 | AC33: 109.6 | AD33: 115
A34: Rural+Urban | B34: 2013 | C34: November | D34: 118.1 | E34: 115.4 | F34: 118.7 | G34: 112.5 | H34: 106.8 | I34: 113.5 | J34: 183.1 | K34: 108.2 | L34: 102.2 | M34: 109.4 | N34: 111.8 | O34: 116.5 | P34: 122.6 | Q34: 113.1 | R34: 114.2 | S34: 111.9 | T34: 113.8 | U34: 111.1 | V34: 111.6 | W34: 111.1 | X34: 109.3 | Y34: 109.5 | Z34: 108.6 | AA34: 111.2 | AB34: 108.1 | AC34: 109.7 | AD34: 116.3
A35: Rural | B35: 2013 | C35: December | D35: 118.4 | E35: 115.9 | F35: 120.4 | G35: 113.8 | H35: 109.5 | I35: 115.5 | J35: 145.7 | K35: 109.5 | L35: 102.9 | M35: 109.8 | N35: 112.1 | O35: 116.8 | P35: 118.7 | Q35: 113.6 | R35: 115.8 | S35: 114 | T35: 115.5 | U35: NA | V35: 112.8 | W35: 112.1 | X35: 110.1 | Y35: 109.9 | Z35: 109.2 | AA35: 111.6 | AB35: 108.1 | AC35: 110.1 | AD35: 115.5
A36: Urban | B36: 2013 | C36: December | D36: 120.5 | E36: 118.1 | F36: 128.5 | G36: 112.8 | H36: 103.4 | I36: 110.7 | J36: 144.8 | K36: 107.1 | L36: 98.6 | M36: 111.9 | N36: 112.1 | O36: 118.1 | P36: 117.8 | Q36: 115 | R36: 114.2 | S36: 110.9 | T36: 113.7 | U36: 110.7 | V36: 110.4 | W36: 111.3 | X36: 109 | Y36: 109.7 | Z36: 108.9 | AA36: 111.4 | AB36: 107.7 | AC36: 109.8 | AD36: 113.3
A37: Rural+Urban | B37: 2013 | C37: December | D37: 119.1 | E37: 116.7 | F37: 123.5 | G37: 113.4 | H37: 107.3 | I37: 113.3 | J37: 145.4 | K37: 108.7 | L37: 101.5 | M37: 110.5 | N37: 112.1 | O37: 117.4 | P37: 118.4 | Q37: 114 | R37: 115.2 | S37: 112.7 | T37: 114.8 | U37: 110.7 | V37: 111.9 | W37: 111.7 | X37: 109.7 | Y37: 109.8 | Z37: 109 | AA37: 111.5 | AB37: 107.9 | AC37: 110 | AD37: 114.5
A38: Rural | B38: 2014 | C38: January | D38: 118.9 | E38: 117.1 | F38: 120.5 | G38: 114.4 | H38: 109 | I38: 115.5 | J38: 123.9 | K38: 109.6 | L38: 101.8 | M38: 110.2 | N38: 112.4 | O38: 117.3 | P38: 116 | Q38: 114 | R38: 116.5 | S38: 114.5 | T38: 116.2 | U38: NA | V38: 113 | W38: 112.6 | X38: 110.6 | Y38: 110.5 | Z38: 109.6 | AA38: 111.8 | AB38: 108.3 | AC38: 110.6 | AD38: 114.2
A39: Urban | B39: 2014 | C39: January | D39: 121.2 | E39: 122 | F39: 129.9 | G39: 113.6 | H39: 102.9 | I39: 112.1 | J39: 118.9 | K39: 107.5 | L39: 96.9 | M39: 112.7 | N39: 112.1 | O39: 119 | P39: 115.5 | Q39: 115.7 | R39: 114.8 | S39: 111.3 | T39: 114.3 | U39: 111.6 | V39: 111 | W39: 111.9 | X39: 109.7 | Y39: 110.8 | Z39: 109.8 | AA39: 111.5 | AB39: 108 | AC39: 110.5 | AD39: 112.9
A40: Rural+Urban | B40: 2014 | C40: January | D40: 119.6 | E40: 118.8 | F40: 124.1 | G40: 114.1 | H40: 106.8 | I40: 113.9 | J40: 122.2 | K40: 108.9 | L40: 100.2 | M40: 111 | N40: 112.3 | O40: 118.1 | P40: 115.8 | Q40: 114.5 | R40: 115.8 | S40: 113.2 | T40: 115.4 | U40: 111.6 | V40: 112.2 | W40: 112.3 | X40: 110.3 | Y40: 110.7 | Z40: 109.7 | AA40: 111.6 | AB40: 108.2 | AC40: 110.6 | AD40: 113.6
...

Sheet Food Bucket May22-23
A1: Sector | B1: Year | C1: Month | D1: Cereals and products | E1: Meat and fish | F1: Egg | G1: Milk and products | H1: Oils and fats | I1: Fruits | J1: Vegetables | K1: Pulses and products | L1: Sugar and Confectionery | M1: Spices | N1: Non-alcoholic beverages | O1: Prepared meals, snacks, sweets etc. | P1: Food and beverages | Q1: General index | R1: Broader Food and Beverages
A2: Rural | B2: 2022 | C2: May | D2: 152.9 | E2: 214.7 | F2: 161.4 | G2: 164.6 | H2: 209.9 | I2: 168 | J2: 160.4 | K2: 165 | L2: 118.9 | M2: 186.6 | N2: 173.2 | O2: 180.4 | P2: 170.8 | Q2: 172.5 | R2: =AVERAGE(D2:P2) -> 171.29231
A3: Urban | B3: 2022 | C3: May | D3: 156.7 | E3: 221.2 | F3: 164.1 | G3: 165.4 | H3: 189.5 | I3: 174.5 | J3: 203.2 | K3: 164.1 | L3: 121.2 | M3: 181.4 | N3: 158.5 | O3: 184.9 | P3: 177.5 | Q3: 170.8 | R3: =AVERAGE(D3:P3) -> 174.01538
A4: Rural+Urban | B4: 2022 | C4: May | D4: 154.1 | E4: 217 | F4: 162.4 | G4: 164.9 | H4: 202.4 | I4: 171 | J4: 174.9 | K4: 164.7 | L4: 119.7 | M4: 184.9 | N4: 167.1 | O4: 182.5 | P4: 173.3 | Q4: 171.7 | R4: =AVERAGE(D4:P4) -> 172.22308
A5: Rural | B5: 2022 | C5: June | D5: 153.8 | E5: 217.2 | F5: 169.6 | G5: 165.4 | H5: 208.1 | I5: 165.8 | J5: 167.3 | K5: 164.6 | L5: 119.1 | M5: 188.9 | N5: 174.2 | O5: 181.9 | P5: 172.4 | Q5: 173.6 | R5: =AVERAGE(D5:P5) -> 172.94615
A6: Urban | B6: 2022 | C6: June | D6: 157.5 | E6: 223.4 | F6: 172.8 | G6: 166.4 | H6: 188.6 | I6: 174.1 | J6: 211.5 | K6: 163.6 | L6: 121.4 | M6: 183.5 | N6: 159.1 | O6: 186.3 | P6: 179.3 | Q6: 171.4 | R6: =AVERAGE(D6:P6) -> 175.96154
A7: Rural+Urban | B7: 2022 | C7: June | D7: 155 | E7: 219.4 | F7: 170.8 | G7: 165.8 | H7: 200.9 | I7: 169.7 | J7: 182.3 | K7: 164.3 | L7: 119.9 | M7: 187.1 | N7: 167.9 | O7: 183.9 | P7: 174.9 | Q7: 172.6 | R7: =AVERAGE(D7:P7) -> 173.99231
A8: Rural | B8: 2022 | C8: July | D8: 155.2 | E8: 210.8 | F8: 174.3 | G8: 166.3 | H8: 202.2 | I8: 169.6 | J8: 168.6 | K8: 164.4 | L8: 119.2 | M8: 191.8 | N8: 174.5 | O8: 183.1 | P8: 172.5 | Q8: 174.3 | R8: =AVERAGE(D8:P8) -> 173.26923
A9: Urban | B9: 2022 | C9: July | D9: 159.3 | E9: 217.1 | F9: 176.6 | G9: 167.1 | H9: 184.8 | I9: 179.5 | J9: 208.5 | K9: 164 | L9: 121.5 | M9: 186.3 | N9: 159.8 | O9: 187.7 | P9: 179.4 | Q9: 172.3 | R9: =AVERAGE(D9:P9) -> 176.27692
A10: Rural+Urban | B10: 2022 | C10: July | D10: 156.5 | E10: 213 | F10: 175.2 | G10: 166.6 | H10: 195.8 | I10: 174.2 | J10: 182.1 | K10: 164.3 | L10: 120 | M10: 190 | N10: 168.4 | O10: 185.2 | P10: 175 | Q10: 173.4 | R10: =AVERAGE(D10:P10) -> 174.33077
A11: Rural | B11: 2022 | C11: August | D11: 159.5 | E11: 204.1 | F11: 168.3 | G11: 167.9 | H11: 198.1 | I11: 169.2 | J11: 173.1 | K11: 167.1 | L11: 120.2 | M11: 195.6 | N11: 174.8 | O11: 184 | P11: 173.9 | Q11: 175.3 | R11: =AVERAGE(D11:P11) -> 173.52308
A12: Urban | B12: 2022 | C12: August | D12: 162.1 | E12: 210.9 | F12: 170.6 | G12: 168.4 | H12: 182.5 | I12: 177.1 | J12: 213.1 | K12: 167.3 | L12: 122.2 | M12: 189.7 | N12: 160.5 | O12: 188.9 | P12: 180.4 | Q12: 173.1 | R12: =AVERAGE(D12:P12) -> 176.43846
A13: Rural+Urban | B13: 2022 | C13: August | D13: 160.3 | E13: 206.5 | F13: 169.2 | G13: 168.1 | H13: 192.4 | I13: 172.9 | J13: 186.7 | K13: 167.2 | L13: 120.9 | M13: 193.6 | N13: 168.8 | O13: 186.3 | P13: 176.3 | Q13: 174.3 | R13: =AVERAGE(D13:P13) -> 174.55385
... A40: Rural+Urban | B40: 2023 | C40: May | D40: 173.7 | E40: 214.3 | F40: 173.2 | G40: 179.5 | H40: 170 | I40: 172.2 | J40: 161 | K40: 175.6 | L40: 122.7 | M40: 218 | N40: 173.4 | O40: 194.2 | P40: 179.1 | Q40: 179.1 | R40: =AVERAGE(D40:P40) -> 177.45385

Sheet Rural+Urban 2017-23
A1: Sector | B1: Year | C1: Month | D1: Cereals and products | E1: Meat and fish | F1: Egg | G1: Milk and products | H1: Oils and fats | I1: Fruits | J1: Vegetables | K1: Pulses and products | L1: Sugar and Confectionery | M1: Spices | N1: Non-alcoholic beverages | O1: Prepared meals, snacks, sweets etc. | P1: Food and beverages | Q1: Pan, tobacco and intoxicants | R1: Clothing | S1: Footwear | T1: Clothing and footwear | U1: Housing | V1: Fuel and light | W1: Household goods and services | X1: Health | Y1: Transport and communication | Z1: Recreation and amusement | AA1: Education | AB1: Personal care and effects | AC1: Miscellaneous | AD1: General index
A2: Rural+Urban | B2: 2016 | C2: January | D2: 126.1 | E2: 134.1 | F2: 128.6 | G2: 129.9 | H2: 115.5 | I2: 125.7 | J2: 141.5 | K2: 170.7 | L2: 97.4 | M2: 132.9 | N2: 122.7 | O2: 135.3 | P2: 131.3 | Q2: 135.2 | R2: 130.3 | S2: 125.1 | T2: 129.5 | U2: 123.4 | V2: 122.7 | W2: 124.2 | X2: 122 | Y2: 111.1 | Z2: 119.8 | AA2: 126.3 | AB2: 114.5 | AC2: 118.5 | AD2: 126.3
A3: Rural+Urban | B3: 2016 | C3: February | D3: 126.4 | E3: 134.2 | F3: 128.7 | G3: 130.3 | H3: 114.8 | I3: 124.9 | J3: 130.3 | K3: 167.4 | L3: 98.8 | M3: 133.6 | N3: 123 | O3: 135.8 | P3: 129.9 | Q3: 135.9 | R3: 130.9 | S3: 125.8 | T3: 130.2 | U3: 124.4 | V3: 123.1 | W3: 124.6 | X3: 122.5 | Y3: 111.4 | Z3: 120.3 | AA3: 126.6 | AB3: 116.6 | AC3: 119.1 | AD3: 126
A4: Rural+Urban | B4: 2016 | C4: March | D4: 126.5 | E4: 135.1 | F4: 124.6 | G4: 130.2 | H4: 114.5 | I4: 126.2 | J4: 129.8 | K4: 164.3 | L4: 100.9 | M4: 133.9 | N4: 123.1 | O4: 136.3 | P4: 129.8 | Q4: 136.5 | R4: 131.3 | S4: 126.1 | T4: 130.5 | U4: 124.9 | V4: 122.4 | W4: 125.1 | X4: 122.9 | Y4: 110.9 | Z4: 120.6 | AA4: 126.9 | AB4: 117.3 | AC4: 119.3 | AD4: 126
A5: Rural+Urban | B5: 2016 | C5: April | D5: 126.6 | E5: 136.8 | F5: 122 | G5: 130.9 | H5: 114.8 | I5: 134.8 | J5: 135 | K5: 167.5 | L5: 106.4 | M5: 134.4 | N5: 123.6 | O5: 136.7 | P5: 131.8 | Q5: 137.1 | R5: 131.8 | S5: 126.4 | T5: 131 | U5: 125.6 | V5: 122.3 | W5: 125.5 | X5: 123.2 | Y5: 112.1 | Z5: 121.1 | AA5: 127.7 | AB5: 118.1 | AC5: 120 | AD5: 127.3
A6: Rural+Urban | B6: 2016 | C6: May | D6: 126.8 | E6: 139.1 | F6: 125.4 | G6: 131.7 | H6: 115 | I6: 136 | J6: 145.1 | K6: 171.7 | L6: 108.7 | M6: 135.3 | N6: 124.2 | O6: 137.4 | P6: 134 | Q6: 137.7 | R6: 132.2 | S6: 126.8 | T6: 131.4 | U6: 126 | V6: 122.7 | W6: 126 | X6: 123.7 | Y6: 112.8 | Z6: 121.5 | AA6: 128.5 | AB6: 119.2 | AC6: 120.7 | AD6: 128.6
A7: Rural+Urban | B7: 2016 | C7: June | D7: 127.7 | E7: 140.5 | F7: 128.3 | G7: 132.6 | H7: 115.5 | I7: 136.5 | J7: 159.7 | K7: 174.3 | L7: 109.9 | M7: 136.3 | N7: 124.4 | O7: 138.1 | P7: 136.8 | Q7: 138.7 | R7: 132.9 | S7: 127.2 | T7: 132 | U7: 125.5 | V7: 123.3 | W7: 126.4 | X7: 124.1 | Y7: 114.2 | Z7: 121.7 | AA7: 129.7 | AB7: 119.4 | AC7: 121.5 | AD7: 130.1
A8: Rural+Urban | B8: 2016 | C8: July | D8: 128.5 | E8: 141.2 | F8: 132.3 | G8: 133.5 | H8: 116.4 | I8: 137.8 | J8: 165.4 | K8: 177.4 | L8: 111.3 | M8: 137.5 | N8: 125 | O8: 138.8 | P8: 138.4 | Q8: 139.3 | R8: 133.5 | S8: 127.6 | T8: 132.7 | U8: 126.4 | V8: 123.4 | W8: 126.9 | X8: 124.5 | Y8: 113.9 | Z8: 122.4 | AA8: 130.8 | AB8: 120.5 | AC8: 121.9 | AD8: 131.1
A9: Rural+Urban | B9: 2016 | C9: August | D9: 129.3 | E9: 139.3 | F9: 131.6 | G9: 134.1 | H9: 116.9 | I9: 138.1 | J9: 159.1 | K9: 175.6 | L9: 112.9 | M9: 138.1 | N9: 125.5 | O9: 139.5 | P9: 137.9 | Q9: 140.2 | R9: 134.1 | S9: 128.2 | T9: 133.2 | U9: 127.3 | V9: 123.6 | W9: 127.4 | X9: 124.8 | Y9: 113.1 | Z9: 122.7 | AA9: 131.7 | AB9: 121.5 | AC9: 122.1 | AD9: 131.1
A10: Rural+Urban | B10: 2016 | C10: September | D10: 129.9 | E10: 138 | F10: 130.5 | G10: 134.4 | H10: 117.2 | I10: 136.1 | J10: 150.7 | K10: 171.5 | L10: 113.8 | M10: 138.8 | N10: 126 | O10: 140.2 | P10: 136.6 | Q10: 141 | R10: 134.6 | S10: 128.6 | T10: 133.8 | U10: 127.9 | V10: 124.1 | W10: 127.9 | X10: 125.4 | Y10: 114.3 | Z10: 122.9 | AA10: 131.8 | AB10: 122.1 | AC10: 122.8 | AD10: 130.9
A11: Rural+Urban | B11: 2016 | C11: October | D11: 130.5 | E11: 137.9 | F11: 130.2 | G11: 134.8 | H11: 117.8 | I11: 134.7 | J11: 151.2 | K11: 172.1 | L11: 114.1 | M11: 139.3 | N11: 126.1 | O11: 141.1 | P11: 137 | Q11: 141.8 | R11: 135.5 | S11: 129.1 | T11: 134.5 | U11: 128.7 | V11: 124.3 | W11: 128.4 | X11: 126.1 | Y11: 115.2 | Z11: 123.5 | AA11: 132.4 | AB11: 122.1 | AC11: 123.4 | AD11: 131.4
A12: Rural+Urban | B12: 2016 | C12: November | D12: 131.4 | E12: 137.8 | F12: 132 | G12: 135 | H12: 118 | I12: 134.1 | J12: 141.9 | K12: 171.7 | L12: 114.1 | M12: 139.7 | N12: 126.2 | O12: 141.8 | P12: 136.1 | Q12: 142 | R12: 135.8 | S12: 129.3 | T12: 135 | U12: 129.1 | V12: 125 | W12: 128.6 | X12: 126.4 | Y12: 115.7 | Z12: 124 | AA12: 132.8 | AB12: 122.6 | AC12: 123.8 | AD12: 131.2
A13: Rural+Urban | B13: 2016 | C13: December | D13: 132.3 | E13: 137.6 | F13: 132.9 | G13: 135.1 | H13: 118.6 | I13: 132.7 | J13: 125.3 | K13: 168.7 | L13: 114.4 | M13: 140.2 | N13: 126.6 | O13: 142.3 | P13: 134 | Q13: 143.1 | R13: 136.3 | S13: 129.8 | T13: 135.4 | U13: 128.5 | V13: 126.6 | W13: 129.2 | X13: 126.9 | Y13: 116 | Z13: 124.2 | AA13: 133.1 | AB13: 121.1 | AC13: 123.9 | AD13: 130.4
... A51: Rural+Urban | B51: 2020 | C51: March | D51: 145.1 | E51: 167 | F51: 148.1 | G51: 151.5 | H51: 131.2 | I51: 142.5 | J51: 157.3 | K51: 141.1 | L51: 113.2 | M51: 153.2 | N51: 136.7 | O51: 159.6 | P51: 148.9 | Q51: 171.2 | R51: 151.2 | S51: 141.9 | T51: 149.8 | U51: 154.5 | V51: 148.9 | W51: 146.4 | X51: 152.3 | Y51: 129.9 | Z51: 143.7 | AA51: 156.1 | AB51: 145.2 | AC51: 143.8 | AD51: 148.6
A52: Rural+Urban | B52: 2020 | C52: April | D52: 148.7 | E52: 167.2 | F52: 148.8 | G52: 155.6 | H52: 135.1 | I52: 149.9 | J52: 168.6 | K52: 150.4 | L52: 120.3 | M52: 157.1 | N52: 136.8 | O52: NA | P52: 151.4 | Q52: NA | R52: NA | S52: NA | T52: NA | U52: 155.6 | V52: 144.1 | W52: NA | X52: 150.7 | Y52: NA | Z52: NA | AA52: NA | AB52: NA | AC52: NA | AD52: 149.3
A53: Rural+Urban | B53: 2020 | C53: May | D53: =AVERAGE(D52,D54) -> 149.15 | E53: =AVERAGE(E52,E54) -> 179.95 | F53: =AVERAGE(F52,F54) -> 150.1 | G53: =AVERAGE(G52,G54) -> 154.45 | H53: =AVERAGE(H52,H54) -> 135.7 | I53: =AVERAGE(I52,I54) -> 148.55 | J53: =AVERAGE(J52,J54) -> 162.55 | K53: =AVERAGE(K52,K54) -> 150.65 | ... AD53: =AVERAGE(AD52,AD54) -> 150.55
A54: Rural+Urban | B54: 2020 | C54: June | D54: 149.6 | E54: 192.7 | F54: 151.4 | G54: 153.3 | H54: 136.3 | I54: 147.2 | J54: 156.5 | K54: 150.9 | L54: 114.2 | M54: 159.5 | N54: 139.4 | O54: 161.8 | P54: 154 | Q54: 183.5 | R54: 152.5 | S54: 144.4 | T54: 151.4 | U54: 154.7 | V54: 141.9 | W54: 146.4 | X54: 154.4 | Y54: 135 | Z54: 148.3 | AA54: 156.4 | AB54: 151.6 | AC54: 147 | AD54: 151.8
A55: Rural+Urban | B55: 2020 | C55: July | D55: 149.6 | E55: 192.7 | F55: 151.4 | G55: 153.3 | H55: 136.3 | I55: 147.2 | J55: 156.5 | K55: 150.9 | L55: 114.2 | M55: 159.5 | N55: 139.4 | O55: 161.8 | P55: 154 | Q55: 183.5 | R55: 152.5 | S55: 144.4 | T55: 151.4 | U55: 154.7 | V55: 141.9 | W55: 146.4 | X55: 154.4 | Y55: 135 | Z55: 148.3 | AA55: 156.4 | AB55: 151.6 | AC55: 147 | AD55: 151.8
A56: Rural+Urban | B56: 2020 | C56: August | D56: 148.9 | E56: 190.9 | F56: 150.8 | G56: 153.3 | H56: 137.4 | I56: 150.4 | J56: 178.1 | K56: 150.4 | L56: 115.1 | M56: 160 | N56: 140.6 | O56: 162.3 | P56: 157 | Q56: 182.6 | R56: 153.1 | S56: 143.4 | T56: 151.7 | U56: 155.5 | V56: 143 | W56: 148.4 | X56: 155 | Y56: 138.5 | Z56: 146 | AA56: 158.5 | AB56: 154.3 | AC56: 149 | AD56: 153.9
A57: Rural+Urban | B57: 2020 | C57: September | D57: 148.4 | E57: 187.1 | F57: 152.5 | G57: 153.6 | H57: 138.2 | I57: 150.9 | J57: 186.7 | K57: 149.8 | L57: 116.4 | M57: 160.3 | N57: 142.2 | O57: 162.9 | P57: 158 | Q57: 184.4 | R57: 153.4 | S57: 144.3 | T57: 152 | U57: 156.3 | V57: 142.9 | W57: 148.7 | X57: 155.6 | Y57: 139.6 | Z57: 146.6 | AA57: 157.5 | AB57: 158.4 | AC57: 150 | AD57: 154.7
A58: Rural+Urban | B58: 2020 | C58: October | D58: 147.5 | E58: 188.9 | F58: 161.4 | G58: 153.6 | H58: 140.1 | I58: 151.2 | J58: 209.2 | K58: 150.9 | L58: 116.2 | M58: 161 | N58: 144 | O58: 163.2 | P58: 161.4 | Q58: 184.3 | R58: 153.7 | S58: 144.6 | T58: 152.3 | U58: 156.5 | V58: 143.1 | W58: 148.7 | X58: 156.3 | Y58: 140.6 | Z58: 146.5 | AA58: 158.5 | AB58: 157 | AC58: 150.4 | AD58: 156.4
A59: Rural+Urban | B59: 2020 | C59: November | D59: 146.8 | E59: 191 | F59: 173.6 | G59: 153.8 | H59: 142.7 | I59: 148.4 | J59: 230 | K59: 156.8 | L59: 115.7 | M59: 161.8 | N59: 146.5 | O59: 163.8 | P59: 164.7 | Q59: 184.8 | R59: 154.3 | S59: 144.9 | T59: 152.8 | U59: 158 | V59: 143.6 | W59: 149.2 | X59: 157.2 | Y59: 140.4 | Z59: 148.4 | AA59: 158.6 | AB59: 156.9 | AC59: 150.7 | AD59: 158.4
A60: Rural+Urban | B60: 2020 | C60: December | D60: 146 | E60: 191 | F60: 175.3 | G60: 154.1 | H60: 146.6 | I60: 147.7 | J60: 230.5 | K60: 160.2 | L60: 115.3 | M60: 163 | N60: 149.2 | O60: 164.8 | P60: 165.4 | Q60: 185.4 | R60: 155 | S60: 145.4 | T60: 153.6 | U60: 158.4 | V60: 144.6 | W60: 149.7 | X60: 158.3 | Y60: 140.7 | Z60: 148.5 | AA60: 159.4 | AB60: 157.1 | AC60: 151.2 | AD60: 158.9
A61: Rural+Urban | B61: 2021 | C61: January | D61: 144.9 | E61: 190.1 | F61: 175.3 | G61: 154.1 | H61: 150.9 | I61: 149.6 | J61: 194.2 | K61: 160.4 | L61: 114.6 | M61: 164 | N61: 151.8 | O61: 165.6 | P61: 161 | Q61: 186.5 | R61: 155.5 | S61: 146.1 | T61: 154.2 | U61: 157.7 | V61: 147.9 | W61: 150 | X61: 159.3 | Y61: 141.9 | Z61: 149.6 | AA61: 159.2 | AB61: 156.8 | AC61: 151.9 | AD61: 157.3
A62: Rural+Urban | B62: 2021 | C62: February | D62: 144.3 | E62: 186.5 | F62: 168.7 | G62: 154.7 | H62: 158.7 | I62: 150.7 | J62: 160 | K62: 158.8 | L62: 112.8 | M62: 164.2 | N62: 155.5 | O62: 167.5 | P62: 156.9 | Q62: 188.3 | R62: 157.2 | S62: 147.4 | T62: 155.8 | U62: 159.8 | V62: 152.4 | W62: 150.9 | X62: 161.3 | Y62: 145.1 | Z62: 151.5 | AA62: 159.5 | AB62: 155.8 | AC62: 153.4 | AD62: 156.6
A63: Rural+Urban | B63: 2021 | C63: March | D63: 144.1 | E63: 192.2 | F63: 163.8 | G63: 154.9 | H63: 163.9 | I63: 153.7 | J63: 149.5 | K63: 159.8 | L63: 112.6 | M63: 163.5 | N63: 156.5 | O63: 168.2 | P63: 156.7 | Q63: 188.1 | R63: 157.8 | S63: 147.9 | T63: 156.4 | U63: 159.9 | V63: 155.5 | W63: 151.2 | X63: 161.7 | Y63: 146.2 | Z63: 152.6 | AA63: 160.2 | AB63: 153.8 | AC63: 153.8 | AD63: 156.8
A64: Rural+Urban | B64: 2021 | C64: April | D64: 144.3 | E64: 198 | F64: 164.6 | G64: 155.4 | H64: 170.1 | I64: 164.4 | J64: 144.1 | K64: 161.7 | L64: 113.1 | M64: 163.9 | N64: 157.6 | O64: 168.9 | P64: 158 | Q64: 188.8 | R64: 158.8 | S64: 148.5 | T64: 157.3 | U64: 161.4 | V64: 155.6 | W64: 151.8 | X64: 162.3 | Y64: 146.6 | Z64: 153.2 | AA64: 160.3 | AB64: 155.4 | AC64: 154.4 | AD64: 157.8
A65: Rural+Urban | B65: 2021 | C65: May | D65: 146.3 | E65: 200.5 | F65: 170.3 | G65: 156.1 | H65: 178.7 | I65: 167.1 | J65: 147.9 | K65: 165.4 | L65: 114.8 | M65: 168.2 | N65: 159.3 | O65: 170.4 | P65: 160.7 | Q65: 191.9 | R65: 161.8 | S65: 152.1 | T65: 160.4 | U65: 161.6 | V65: 159.4 | W65: 154.7 | X65: 165.8 | Y65: 148.9 | Z65: 155.8 | AA65: 161.2 | AB65: 158.6 | AC65: 156.8 | AD65: 160.4
... A89: Rural+Urban | B89: 2023 | C89: May | D89: 173.7 | E89: 214.3 | F89: 173.2 | G89: 179.5 | H89: 170 | I89: 172.2 | J89: 161 | K89: 175.6 | L89: 122.7 | M89: 218 | N89: 173.4 | O89: 194.2 | P89: 179.1 | Q89: 201 | R89: 187.3 | S89: 179.7 | T89: 186.2 | U89: 175.6 | V89: 182.8 | W89: 175.2 | X89: 185.7 | Y89: 164.8 | Z89: 171.2 | AA89: 177.1 | AB89: 185.2 | AC89: 175.7 | AD89: 179.1

Sheet Broader Category
A1: Category | B1: Broader Category
A2: Cereals and products | B2: Food and Beverages
A3: Meat and fish | B3: Food and Beverages
A4: Egg | B4: Food and Beverages
A5: Milk and products | B5: Food and Beverages
A6: Oils and fats | B6: Food and Beverages
A7: Fruits | B7: Food and Beverages
A8: Vegetables | B8: Food and Beverages
A9: Pulses and products | B9: Food and Beverages
A10: Sugar and Confectionery | B10: Food and Beverages
A11: Spices | B11: Food and Beverages
A12: Non-alcoholic beverages | B12: Food and Beverages
... A27: Miscellaneous | B27: Miscellaneous

Sheet DASHBOARD

Sheet Ans 5(b)
A1: Year | B1: Month | C1: Imported Crude Oil Price | D1: Cereals and products | E1: Meat and fish | F1: Egg | G1: Milk and products | H1: Oils and fats | I1: Fruits | J1: Vegetables | K1: Pulses and products | L1: Sugar and Confectionery | M1: Spices | N1: Non-alcoholic beverages | O1: Prepared meals, snacks, sweets etc. | P1: Food and beverages | Q1: Pan, tobacco and intoxicants | R1: Clothing | S1: Footwear | T1: Clothing and footwear | U1: Housing | V1: Fuel and light | W1: Household goods and services | X1: Health | Y1: Transport and communication | Z1: Recreation and amusement | AA1: Education | AB1: Personal care and effects | AC1: Miscellaneous | AD1: General index
A2: 2021 | B2: 33329 | C2: 63.396977 | D2: 144.3 | E2: 198 | F2: 164.6 | G2: 155.4 | H2: 170.1 | I2: 164.4 | J2: 144.1 | K2: 161.7 | L2: 113.1 | M2: 163.9 | N2: 157.6 | O2: 168.9 | P2: 158 | Q2: 188.8 | R2: 158.8 | S2: 148.5 | T2: 157.3 | U2: 161.4 | V2: 155.6 | W2: 151.8 | X2: 162.3 | Y2: 146.6 | Z2: 153.2 | AA2: 160.3 | AB2: 155.4 | AC2: 154.4 | AD2: 157.8
A3: 2021 | B3: 33359 | C3: 66.953085 | D3: 146.3 | E3: 200.5 | F3: 170.3 | G3: 156.1 | H3: 178.7 | I3: 167.1 | J3: 147.9 | K3: 165.4 | L3: 114.8 | M3: 168.2 | N3: 159.3 | O3: 170.4 | P3: 160.7 | Q3: 191.9 | R3: 161.8 | S3: 152.1 | T3: 160.4 | U3: 161.6 | V3: 159.4 | W3: 154.7 | X3: 165.8 | Y3: 148.9 | Z3: 155.8 | AA3: 161.2 | AB3: 158.6 | AC3: 156.8 | AD3: 160.4
A4: 2021 | B4: 33390 | C4: 71.982647 | D4: 146.7 | E4: 202 | F4: 180.7 | G4: 156.2 | H4: 183.7 | I4: 164.6 | J4: 155.4 | K4: 166 | L4: 115.1 | M4: 168.5 | N4: 160 | O4: 172.4 | P4: 162.6 | Q4: 190.8 | R4: 162.2 | S4: 151.8 | T4: 160.7 | U4: 160.5 | V4: 159.8 | W4: 154.8 | X4: 166.3 | Y4: 150.7 | Z4: 154.9 | AA4: 161.7 | AB4: 158.8 | AC4: 157.6 | AD4: 161.3
A5: 2021 | B5: 33420 | C5: 73.539061 | D5: 146.4 | E5: 206.8 | F5: 182.2 | G5: 157.5 | H5: 182.1 | I5: 163.9 | J5: 164.2 | K5: 164 | L5: 114.5 | M5: 168.3 | N5: 160.9 | O5: 172.2 | P5: 164 | Q5: 191.2 | R5: 162.8 | S5: 153.1 | T5: 161.4 | U5: 161.5 | V5: 160.7 | W5: 155.8 | X5: 167 | Y5: 153.1 | Z5: 155.3 | AA5: 163.2 | AB5: 160.1 | AC5: 159 | AD5: 162.5
A6: 2021 | B6: 33451 | C6: 69.804724 | D6: 146.6 | E6: 204 | F6: 172.8 | G6: 158.4 | H6: 188 | I6: 156.8 | J6: 162.2 | K6: 164.1 | L6: 119.7 | M6: 168.8 | N6: 162.7 | O6: 173.9 | P6: 164 | Q6: 192.1 | R6: 164.5 | S6: 155.3 | T6: 163.2 | U6: 162.1 | V6: 162.6 | W6: 157.5 | X6: 168.4 | Y6: 154 | Z6: 157.6 | AA6: 163.8 | AB6: 160 | AC6: 160 | AD6: 163.2
A7: 2021 | B7: 33482 | C7: 73.130738 | D7: 146.6 | E7: 204 | F7: 172.8 | G7: 158.4 | H7: 188 | I7: 156.7 | J7: 162.3 | K7: 164.1 | L7: 119.7 | M7: 168.8 | N7: 162.7 | O7: 173.9 | P7: 164 | Q7: 192.1 | R7: 164.6 | S7: 155.3 | T7: 163.3 | U7: 162.1 | V7: 162.6 | W7: 157.5 | X7: 168.4 | Y7: 154 | Z7: 157.7 | AA7: 163.7 | AB7: 160 | AC7: 160 | AD7: 163.2
A8: 2021 | B8: 33512 | C8: 82.107394 | D8: 147.4 | E8: 204.6 | F8: 171.2 | G8: 158.7 | H8: 190.6 | I8: 155.7 | J8: 185.3 | K8: 165.2 | L8: 121.9 | M8: 169.3 | N8: 163.2 | O8: 174.7 | P8: 167.7 | Q8: 192.7 | R8: 165.7 | S8: 156.3 | T8: 164.3 | U8: 163.6 | V8: 164.2 | W8: 158.4 | X8: 169.1 | Y8: 155.7 | Z8: 158.6 | AA8: 163.9 | AB8: 160.8 | AC8: 161 | AD8: 165.5
A9: 2021 | B9: 33543 | C9: 80.637301 | D9: 148.2 | E9: 201.6 | F9: 173 | G9: 159.3 | H9: 190.1 | I9: 156.5 | J9: 199.2 | K9: 165.3 | L9: 122.4 | M9: 169.6 | N9: 163.7 | O9: 175.5 | P9: 169.7 | Q9: 192.9 | R9: 167.2 | S9: 157.4 | T9: 165.8 | U9: 164.2 | V9: 163.9 | W9: 159.3 | X9: 169.9 | Y9: 154.8 | Z9: 159.8 | AA9: 164.3 | AB9: 162.2 | AC9: 161.4 | AD9: 166.7
A10: 2021 | B10: 33573 | C10: 73.298824 | D10: 148.7 | E10: 198.8 | F10: 177.9 | G10: 159.9 | H10: 187.6 | I10: 154.9 | J10: 188.3 | K10: 164.4 | L10: 121 | M10: 170.5 | N10: 164.2 | O10: 176.5 | P10: 168.2 | Q10: 192.4 | R10: 168.5 | S10: 158.7 | T10: 167 | U10: 163.4 | V10: 164.1 | W10: 160.2 | X10: 170.6 | Y10: 155.7 | Z10: 160.6 | AA10: 164.4 | AB10: 162.6 | AC10: 162 | AD10: 166.2
A11: 2022 | B11: 33604 | C11: 84.666319 | D11: 149.5 | E11: 198.7 | F11: 178.8 | G11: 160.5 | H11: 184.7 | I11: 153.7 | J11: 174.3 | K11: 163.9 | L11: 120 | M11: 172.1 | N11: 164.3 | O11: 177.3 | P11: 166.4 | Q11: 192.2 | R11: 169.9 | S11: 160.7 | T11: 168.5 | U11: 164.5 | V11: 164.2 | W11: 161.1 | X11: 171.4 | Y11: 156.5 | Z11: 161.2 | AA11: 164.7 | AB11: 163 | AC11: 162.7 | AD11: 165.7
A12: 2022 | B12: 33635 | C12: 94.067715 | D12: 150 | E12: 200.6 | F12: 175.8 | G12: 160.7 | H12: 184.9 | I12: 153.7 | J12: 169.7 | K12: 163.7 | L12: 118.9 | M12: 174.3 | N12: 164.7 | O12: 178 | P12: 166.2 | Q12: 192.8 | R12: 170.8 | S12: 162.4 | T12: 169.6 | U12: 165.5 | V12: 165.7 | W12: 161.8 | X12: 172.2 | Y12: 156.9 | Z12: 162.1 | AA12: 165.4 | AB12: 164.4 | AC12: 163.5 | AD12: 166.1
A13: 2022 | B13: 33664 | C13: 112.87479 | D13: 151.3 | E13: 210.7 | F13: 167.8 | G13: 162.2 | H13: 194.6 | I13: 157.6 | J13: 166.9 | K13: 163.9 | L13: 118.8 | M13: 177.4 | N13: 165.3 | O13: 179.3 | P13: 168.4 | Q13: 193.7 | R13: 172.1 | S13: 164.6 | T13: 171.1 | U13: 165.3 | V13: 167.2 | W13: 162.8 | X13: 173 | Y13: 157.9 | Z13: 163.3 | AA13: 166 | AB13: 167.2 | AC13: 164.6 | AD13: 167.7
... A27: 2023 | B27: 33359 | C27: 74.981548 | D27: 173.7 | E27: 214.3 | F27: 173.2 | G27: 179.5 | H27: 170 | I27: 172.2 | J27: 161 | K27: 175.6 | L27: 122.7 | M27: 218 | N27: 173.4 | O27: 194.2 | P27: 179.1 | Q27: 201 | R27: 187.3 | S27: 179.7 | T27: 186.2 | U27: 175.6 | V27: 182.8 | W27: 175.2 | X27: 185.7 | Y27: 164.8 | Z27: 171.2 | AA27: 177.1 | AB27: 185.2 | AC27: 175.7 | AD27: 179.1
E31: CORELL WITH OTHER CPI
E32: Cereals and products | H32: =CORREL(C2:C27,D2:D27) -> 0.098634814
E33: Meat and fish | H33: =CORREL(C2:C27,E2:E27) -> 0.67992538
E34: Egg | H34: =CORREL(C2:C27,F2:F27) -> -0.3315438
E35: Milk and products | H35: =CORREL(C2:C27,G2:G27) -> 0.18126116
E36: Oils and fats | H36: =CORREL(C2:C27,H2:H27) -> 0.7587992 | K36: Insight- | L36: Imported Crude Oil has highest correlation with Oils and Fats of 0.75
E37: Fruits | H37: =CORREL(C2:C27,I2:I27) -> 0.29443289
E38: Vegetables | H38: =CORREL(C2:C27,J2:J27) -> 0.4491395
E39: Pulses and products | H39: =CORREL(C2:C27,K2:K27) -> -0.12939252
E40: Sugar and Confectionery | H40: =CORREL(C2:C27,L2:L27) -> 0.29673945
E41: Spices | H41: =CORREL(C2:C27,M2:M27) -> 0.18263938
E42: Non-alcoholic beverages | H42: =CORREL(C2:C27,N2:N27) -> 0.34204293
E43: Prepared meals, snacks, sweets etc. | H43: =CORREL(C2:C27,O2:O27) -> 0.30194792
E44: Food and beverages | H44: =CORREL(C2:C27,P2:P27) -> 0.43280544
E45: Pan, tobacco and intoxicants | H45: =CORREL(C2:C27,Q2:Q27) -> 0.1493222
E46: Clothing | H46: =CORREL(C2:C27,R2:R27) -> 0.34584309
E47: Footwear | H47: =CORREL(C2:C27,S2:S27) -> 0.38937866
E48: Clothing and footwear | H48: =CORREL(C2:C27,T2:T27) -> 0.35337628
E49: Housing | H49: =CORREL(C2:C27,U2:U27) -> 0.23713189
E50: Fuel and light | H50: =CORREL(C2:C27,V2:V27) -> 0.3952237
E51: Household goods and services | H51: =CORREL(C2:C27,W2:W27) -> 0.32600399
E52: Health | H52: =CORREL(C2:C27,X2:X27) -> 0.27018091
E53: Transport and communication | H53: =CORREL(C2:C27,Y2:Y27) -> 0.51557043
E54: Recreation and amusement | H54: =CORREL(C2:C27,Z2:Z27) -> 0.42044385
E55: Education | H55: =CORREL(C2:C27,AA2:AA27) -> 0.26029261
E56: Personal care and effects | H56: =CORREL(C2:C27,AB2:AB27) -> 0.23018482
...

Sheet Ans5(a)
B1: 33329 | C1: 33359 | D1: 33390 | E1: 33420 | F1: 33451 | G1: 33482 | H1: 33512 | I1: 33543 | J1: 33573 | K1: 33604 | L1: 33635 | M1: 33664
A2: 2021-22 | B2: 63.396977 | C2: 66.953085 | D2: 71.982647 | E2: 73.539061 | F2: 69.804724 | G2: 73.130738 | H2: 82.107394 | I2: 80.637301 | J2: 73.298824 | K2: 84.666319 | L2: 94.067715 | M2: 112.87479
A3: 2022-23 | B3: 102.966 | C3: 109.50504 | D3: 116.01139 | E3: 105.49125 | F3: 97.404465 | G3: 90.706345 | H3: 91.698949 | I3: 87.552266 | J3: 78.100942 | K3: 80.92227 | L3: 82.278707 | M3: 78.53948
A4: 2023-24 | B4: 83.755358 | C4: 74.981548 | D4: 74.928252 | E4: 80.368492 | F4: 86.426704 | G4: 93.539339 | H4: 90.080343 | I4: 83.455368 | J4: 77.419722 | K4: 79.216542 | L4: 81.621881 | M4: 84.486883
A9: Year | B9: Month | C9: Imported Crude Oil Price | D9: Change Mom
A10: 2021 | B10: 33329 | C10: 63.396977 | D10: 0
A11: 2021 | B11: 33359 | C11: 66.953085 | D11: =(C11-C10)/C10 -> 0.056092712
A12: 2021 | B12: 33390 | C12: 71.982647 | D12: =(C12-C11)/C11 -> 0.0751207
A13: 2021 | B13: 33420 | C13: 73.539061 | D13: =(C13-C12)/C12 -> 0.021622059
A14: 2021 | B14: 33451 | C14: 69.804724 | D14: =(C14-C13)/C13 -> -0.050780307
A15: 2021 | B15: 33482 | C15: 73.130738 | D15: =(C15-C14)/C14 -> 0.047647403
A16: 2021 | B16: 33512 | C16: 82.107394 | D16: =(C16-C15)/C15 -> 0.12274805
A17: 2021 | B17: 33543 | C17: 80.637301 | D17: =(C17-C16)/C16 -> -0.017904511
A18: 2021 | B18: 33573 | C18: 73.298824 | D18: =(C18-C17)/C17 -> -0.091005991
A19: 2022 | B19: 33604 | C19: 84.666319 | D19: =(C19-C18)/C18 -> 0.15508428
A20: 2022 | B20: 33635 | C20: 94.067715 | D20: =(C20-C19)/C19 -> 0.11104057
A21: 2022 | B21: 33664 | C21: 112.87479 | D21: =(C21-C20)/C20 -> 0.19993127
A22: 2022 | B22: 33329 | C22: 102.966 | D22: =(C22-C21)/C21 -> -0.087785718
... A45: 2024 | B45: 33664 | C45: 84.486883 | D45: =(C45-C44)/C44 -> 0.035100903
A51: Row Labels | B51: %Change Mom
A52: 2021 | B52: 0.16354011
A53: Apr | B53: 0
A54: May | B54: 0.056092712
A55: Jun | B55: 0.0751207
A56: Jul | B56: 0.021622059
A57: Aug | B57: -0.050780307
A58: Sep | B58: 0.047647403
A59: Oct | B59: 0.12274805
A60: Nov | B60: -0.017904511
A61: Dec | B61: -0.091005991
A62: 2022 | B62: 0.12285862
A63: Jan | B63: 0.15508428
A64: Feb | B64: 0.11104057
A65: Mar | B65: 0.19993127
A66: Apr | B66: -0.087785718
A67: May | B67: 0.063506789
A68: Jun | B68: 0.059415963
A69: Jul | B69: -0.090681942
A70: Aug | B70: -0.076658321
A71: Sep | B71: -0.068766053
...

Sheet Ans4
A1: Sector | B1: Year | C1: Month | D1: Cereals and products | E1: Meat and fish | F1: Egg | G1: Milk and products | H1: Oils and fats | I1: Fruits | J1: Vegetables | K1: Pulses and products | L1: Sugar and Confectionery | M1: Spices | N1: Non-alcoholic beverages | O1: Prepared meals, snacks, sweets etc. | P1: Food and beverages | Q1: Clothing | R1: Footwear | S1: Clothing and footwear | T1: Fuel and light | U1: Health | V1: Transport and communication | W1: Education | X1: Average | Y1: Change in Inflation | Z1: Time Period
A2: Rural+Urban | B2: 2018 | C2: January | D2: 136 | E2: 144.2 | F2: 143.7 | G2: 141.1 | H2: 120.7 | I2: 141.3 | J2: 151.6 | K2: 127.3 | L2: 118.8 | M2: 137.5 | N2: 129 | O2: 149.5 | P2: 139.2 | Q2: 143.5 | R2: 135.5 | S2: 142.3 | T2: 136.6 | U2: 133.3 | V2: 119.3 | W2: 139 | X2: =AVERAGE(D2:W2) -> 136.47 | Y2: 0 | Z2: =CONCATENATE(LEFT(C2,3),RIGHT(B2,2)) -> Jan18
A3: Rural+Urban | B3: 2018 | C3: February | D3: 135.9 | E3: 143.5 | F3: 140.3 | G3: 140.9 | H3: 120.4 | I3: 142.9 | J3: 140.5 | K3: 125.8 | L3: 117.1 | M3: 137.3 | N3: 128.6 | O3: 149.6 | P3: 137.6 | Q3: 143.8 | R3: 135.6 | S3: 142.6 | T3: 136.7 | U3: 133.8 | V3: 120.2 | W3: 139 | X3: =AVERAGE(D3:W3) -> 135.605 | Y3: =(X3-X2)/X2 -> -0.0063383894 | Z3: =CONCATENATE(LEFT(C3,3),RIGHT(B3,2)) -> Feb18
A4: Rural+Urban | B4: 2018 | C4: March | D4: 136.2 | E4: 143.6 | F4: 138.3 | G4: 141.2 | H4: 120.7 | I4: 146.2 | J4: 134.6 | K4: 124.6 | L4: 116.1 | M4: 137.8 | N4: 129.1 | O4: 150.4 | P4: 137.2 | Q4: 144.3 | R4: 136.2 | S4: 143.1 | T4: 136.5 | U4: 134.3 | V4: 121 | W4: 139.8 | X4: =AVERAGE(D4:W4) -> 135.56 | Y4: =(X4-X3)/X3 -> -0.00033184617 | Z4: =CONCATENATE(LEFT(C4,3),RIGHT(B4,2)) -> Mar18
A5: Rural+Urban | B5: 2018 | C5: April | D5: 136.4 | E5: 144.4 | F5: 133.9 | G5: 141.6 | H5: 121 | I5: 153.5 | J5: 132.6 | K5: 123.5 | L5: 113.7 | M5: 138.2 | N5: 129.6 | O5: 151.2 | P5: 137.5 | Q5: 145.3 | R5: 136.7 | S5: 144 | T5: 136.5 | U5: 135.2 | V5: 121.9 | W5: 141.4 | X5: =AVERAGE(D5:W5) -> 135.905 | Y5: =(X5-X4)/X4 -> 0.0025449985 | Z5: =CONCATENATE(LEFT(C5,3),RIGHT(B5,2)) -> Apr18
A6: Rural+Urban | B6: 2018 | C6: May | D6: 136.6 | E6: 146.6 | F6: 133.6 | G6: 142.1 | H6: 121 | I6: 154.6 | J6: 135.6 | K6: 122.3 | L6: 109.6 | M6: 138.1 | N6: 129.9 | O6: 151.7 | P6: 138.1 | Q6: 146 | R6: 137.4 | S6: 144.7 | T6: 136.9 | U6: 136 | V6: 122.9 | W6: 142.1 | X6: =AVERAGE(D6:W6) -> 136.29 | Y6: =(X6-X5)/X5 -> 0.0028328612 | Z6: =CONCATENATE(LEFT(C6,3),RIGHT(B6,2)) -> May18
A7: Rural+Urban | B7: 2018 | C7: June | D7: 136.9 | E7: 148.7 | F7: 135.6 | G7: 142.3 | H7: 121.3 | I7: 153.2 | J7: 143.7 | K7: 121.4 | L7: 111.1 | M7: 138.4 | N7: 130.3 | O7: 151.8 | P7: 139.4 | Q7: 146.4 | R7: 138.1 | S7: 145.2 | T7: 138.1 | U7: 136.2 | V7: 123.7 | W7: 142.8 | X7: =AVERAGE(D7:W7) -> 137.23 | Y7: =(X7-X6)/X6 -> 0.0068970577 | Z7: =CONCATENATE(LEFT(C7,3),RIGHT(B7,2)) -> Jun18
A8: Rural+Urban | B8: 2018 | C8: July | D8: 137.5 | E8: 149.1 | F8: 139.2 | G8: 142.5 | H8: 121.4 | I8: 151.6 | J8: 155.9 | K8: 121.7 | L8: 113.5 | M8: 138.9 | N8: 130.3 | O8: 152.3 | P8: 141.4 | Q8: 146.8 | R8: 138.4 | S8: 145.6 | T8: 139.7 | U8: 137 | V8: 123.6 | W8: 144.7 | X8: =AVERAGE(D8:W8) -> 138.555 | Y8: =(X8-X7)/X7 -> 0.0096553232 | Z8: =CONCATENATE(LEFT(C8,3),RIGHT(B8,2)) -> Jul18
A9: Rural+Urban | B9: 2018 | C9: August | D9: 138.3 | E9: 148 | F9: 138.1 | G9: 142.6 | H9: 122.2 | I9: 150.6 | J9: 156.6 | K9: 122.4 | L9: 114.7 | M9: 139.4 | N9: 131.1 | O9: 153 | P9: 141.7 | Q9: 147.3 | R9: 138.8 | S9: 146.1 | T9: 140.9 | U9: 137.7 | V9: 124.3 | W9: 146 | X9: =AVERAGE(D9:W9) -> 138.99 | Y9: =(X9-X8)/X8 -> 0.0031395475 | Z9: =CONCATENATE(LEFT(C9,3),RIGHT(B9,2)) -> Aug18
A10: Rural+Urban | B10: 2018 | C10: September | D10: 138.6 | E10: 145.8 | F10: 135.1 | G10: 142.9 | H10: 122.1 | I10: 145.4 | J10: 150 | K10: 121.4 | L10: 113.7 | M10: 139.5 | N10: 130.8 | O10: 153.8 | P10: 140.4 | Q10: 147.7 | R10: 139.1 | S10: 146.5 | T10: 142.3 | U10: 138.4 | V10: 126 | W10: 146.2 | X10: =AVERAGE(D10:W10) -> 138.285 | Y10: =(X10-X9)/X9 -> -0.0050723074 | Z10: =CONCATENATE(LEFT(C10,3),RIGHT(B10,2)) -> Sep18
A11: Rural+Urban | B11: 2018 | C11: October | D11: 137.4 | E11: 149.5 | F11: 137.3 | G11: 141.9 | H11: 121.1 | I11: 142.5 | J11: 146.7 | K11: 119.1 | L11: 111.9 | M11: 141 | N11: 133.6 | O11: 154.5 | P11: 139.7 | Q11: 148 | R11: 139.2 | S11: 146.8 | T11: 145.3 | U11: 142.1 | V11: 125.5 | W11: 147.8 | X11: =AVERAGE(D11:W11) -> 138.545 | Y11: =(X11-X10)/X10 -> 0.001880175 | Z11: =CONCATENATE(LEFT(C11,3),RIGHT(B11,2)) -> Oct18
A12: Rural+Urban | B12: 2018 | C12: November | D12: 137.4 | E12: 149.2 | F12: 137.1 | G12: 141.8 | H12: 121.1 | I12: 142.8 | J12: 146.7 | K12: 119.1 | L12: 111.9 | M12: 140.9 | N12: 133.5 | O12: 154.5 | P12: 139.7 | Q12: 148 | R12: 139.1 | S12: 146.7 | T12: 145.1 | U12: 142.1 | V12: 125.5 | W12: 147.8 | X12: =AVERAGE(D12:W12) -> 138.5 | Y12: =(X12-X11)/X11 -> -0.00032480422 | Z12: =CONCATENATE(LEFT(C12,3),RIGHT(B12,2)) -> Nov18
A13: Rural+Urban | B13: 2018 | C13: December | D13: 137.5 | E13: 150.5 | F13: 138.8 | G13: 142.1 | H13: 122 | I13: 139.4 | J13: 135.2 | K13: 119.8 | L13: 110.3 | M13: 140.6 | N13: 133.8 | O13: 154.6 | P13: 138.2 | Q13: 148.1 | R13: 139.4 | S13: 146.8 | T13: 142.7 | U13: 144.9 | V13: 123.6 | W13: 150.1 | X13: =AVERAGE(D13:W13) -> 137.92 | Y13: =(X13-X12)/X12 -> -0.0041877256 | Z13: =CONCATENATE(LEFT(C13,3),RIGHT(B13,2)) -> Dec18
A14: Rural+Urban | B14: 2019 | C14: January | D14: 137.1 | E14: 151.4 | F14: 140.2 | G14: 142.1 | H14: 121.8 | I14: 135.4 | J14: 131.3 | K14: 120.3 | L14: 109.1 | M14: 139.4 | N14: 133.3 | O14: 154.6 | P14: 137.4 | Q14: 147.6 | R14: 139 | S14: 146.4 | T14: 139.5 | U14: 145.1 | V14: 123.3 | W14: 150.2 | X14: =AVERAGE(D14:W14) -> 137.225 | Y14: =(X14-X13)/X13 -> -0.0050391531 | Z14: =CONCATENATE(LEFT(C14,3),RIGHT(B14,2)) -> Jan19
... A48: Rural+Urban | B48: 2021 | C48: December | D48: 148.7 | E48: 198.8 | F48: 177.9 | G48: 159.9 | H48: 187.6 | I48: 154.9 | J48: 188.3 | K48: 164.4 | L48: 121 | M48: 170.5 | N48: 164.2 | O48: 176.5 | P48: 168.2 | Q48: 168.5 | R48: 158.7 | S48: 167 | T48: 164.1 | U48: 170.6 | V48: 155.7 | W48: 164.4 | X48: =AVERAGE(D48:W48) -> 166.495 | Y48: =(X48-X47)/X47 -> -0.0022472583 | Z48: =CONCATENATE(LEFT(C48,3),RIGHT(B48,2)) -> Dec21
A58: Row Labels | B58: %Change in Inflation
A59: 2018 | B59: 0.01069489
A60: January | B60: 0
A61: February | B61: -0.0063383894
A62: March | B62: -0.00033184617
A63: April | B63: 0.0025449985
A64: May | B64: 0.0028328612
A65: June | B65: 0.0068970577
A66: July | B66: 0.0096553232
A67: August | B67: 0.0031395475
A68: September | B68: -0.0050723074
A69: October | B69: 0.001880175
A70: November | B70: -0.00032480422
A71: December | B71: -0.0041877256
A72: 2019 | B72: 0.073059802
A73: January | B73: -0.0050391531
A74: February | B74: 0.0017125159
A75: March | B75: 0.0032736796
A76: May | B76: 0.012145602
A77: June | B77: 0.0087760146
A78: July | B78: 0.0089127193
A79: August | B79: 0.0036954915
A80: September | B80: 0.00459359
A81: October | B81: 0.010750812
A82: November | B82: 0.01001485
...

Sheet Ans3
A1: Sector | B1: Year | C1: Month | D1: Broader Food and Beverages | E1: Monthly Inflation Rate | F1: Month Yearwise | G1: Absolute change in inflation | H1: Cereals and products | I1: Meat and fish | J1: Egg | K1: Milk and products | L1: Oils and fats | M1: Fruits | N1: Vegetables | O1: Pulses and products | P1: Sugar and Confectionery | Q1: Spices | R1: Non-alcoholic beverages | S1: Prepared meals, snacks, sweets etc. | T1: Food and beverages
A2: Rural+Urban | B2: 2022 | C2: June | D2: 173.99231 | E2: =((D2-172.2)/172.2) -> 0.010408291 | F2: =_xlfn.TEXTJOIN( ,TRUE,C2,B2) -> June2022 | G2: =ABS(E2) -> 0.010408291 | H2: 155 | I2: 219.4 | J2: 170.8 | K2: 165.8 | L2: 200.9 | M2: 169.7 | N2: 182.3 | O2: 164.3 | P2: 119.9 | Q2: 187.1 | R2: 167.9 | S2: 183.9 | T2: 174.9
A3: Rural+Urban | B3: 2022 | C3: July | D3: 174.33077 | E3: =((D3-D2)/D2)*100 -> 0.19452673 | F3: =_xlfn.TEXTJOIN( ,TRUE,C3,B3) -> July2022 | G3: =ABS(E3) -> 0.19452673 | H3: 156.5 | I3: 213 | J3: 175.2 | K3: 166.6 | L3: 195.8 | M3: 174.2 | N3: 182.1 | O3: 164.3 | P3: 120 | Q3: 190 | R3: 168.4 | S3: 185.2 | T3: 175
A4: Rural+Urban | B4: 2022 | C4: August | D4: 174.55385 | E4: =((D4-D3)/D3)*100 -> 0.12796188 | F4: =_xlfn.TEXTJOIN( ,TRUE,C4,B4) -> August2022 | G4: =ABS(E4) -> 0.12796188 | H4: 160.3 | I4: 206.5 | J4: 169.2 | K4: 168.1 | L4: 192.4 | M4: 172.9 | N4: 186.7 | O4: 167.2 | P4: 120.9 | Q4: 193.6 | R4: 168.8 | S4: 186.3 | T4: 176.3
A5: Rural+Urban | B5: 2022 | C5: September | D5: 175.45385 | E5: =((D5-D4)/D4)*100 -> 0.51560021 | F5: =_xlfn.TEXTJOIN( ,TRUE,C5,B5) -> September2022 | G5: =ABS(E5) -> 0.51560021 | H5: 163.5 | I5: 209.2 | J5: 169.7 | K5: 169.7 | L5: 188.7 | M5: 165.7 | N5: 191.8 | O5: 169.1 | P5: 121.6 | Q5: 197.3 | R5: 169.4 | S5: 187.4 | T5: 177.8
A6: Rural+Urban | B6: 2022 | C6: October | D6: 176.71538 | E6: =((D6-D5)/D5)*100 -> 0.71901442 | F6: =_xlfn.TEXTJOIN( ,TRUE,C6,B6) -> October2022 | G6: =ABS(E6) -> 0.71901442 | H6: 165.2 | I6: 210.9 | J6: 170.9 | K6: 170.9 | L6: 186.5 | M6: 163.8 | N6: 199.7 | O6: 169.8 | P6: 121.9 | Q6: 199.9 | R6: 169.9 | S6: 188.3 | T6: 179.6
A7: Rural+Urban | B7: 2022 | C7: November | D7: 176.67692 | E7: =((D7-D6)/D6)*100 -> -0.02176468 | F7: =_xlfn.TEXTJOIN( ,TRUE,C7,B7) -> November2022 | G7: =ABS(E7) -> 0.02176468 | H7: 167.4 | I7: 209.4 | J7: 181.4 | K7: 172.3 | L7: 188.9 | M7: 160.7 | N7: 183.1 | O7: 170.5 | P7: 122.1 | Q7: 202.8 | R7: 170.4 | S7: 189.5 | T7: 178.3
A8: Rural+Urban | B8: 2022 | C8: December | D8: 175.64615 | E8: =((D8-D7)/D7)*100 -> -0.58342041 | F8: =_xlfn.TEXTJOIN( ,TRUE,C8,B8) -> December2022 | G8: =ABS(E8) -> 0.58342041 | H8: 169.2 | I8: 209 | J8: 190.2 | K8: 173.6 | L8: 188.5 | M8: 158 | N8: 159.9 | O8: 170.8 | P8: 121.8 | Q8: 205.2 | R8: 171 | S8: 190.3 | T8: 175.9
A9: Rural+Urban | B9: 2023 | C9: January | D9: 176.36154 | E9: =((D9-D8)/D8)*100 -> 0.40728738 | F9: =_xlfn.TEXTJOIN( ,TRUE,C9,B9) -> January2023 | G9: =ABS(E9) -> 0.40728738 | H9: 173.8 | I9: 210.7 | J9: 194.5 | K9: 174.6 | L9: 187.2 | M9: 158.3 | N9: 153.9 | O9: 170.9 | P9: 121.1 | Q9: 208.4 | R9: 171.4 | S9: 191.2 | T9: 176.7
A10: Rural+Urban | B10: 2023 | C10: February | D10: 175.31538 | E10: =((D10-D9)/D9)*100 -> -0.59318707 | F10: =_xlfn.TEXTJOIN( ,TRUE,C10,B10) -> February2023 | G10: =ABS(E10) -> 0.59318707 | H10: 174.4 | I10: 207.7 | J10: 175.2 | K10: 177.3 | L10: 179.3 | M10: 169.5 | N10: 152.7 | O10: 171 | P10: 120 | Q10: 209.7 | R10: 172.3 | S10: 193 | T10: 177
A11: Rural+Urban | B11: 2023 | C11: March | D11: 175.32308 | E11: =((D11-D10)/D10)*100 -> 0.0043876969 | F11: =_xlfn.TEXTJOIN( ,TRUE,C11,B11) -> March2023 | G11: =ABS(E11) -> 0.0043876969 | H11: 174.4 | I11: 207.7 | J11: 175.2 | K11: 177.3 | L11: 179.2 | M11: 169.5 | N11: 152.8 | O11: 171.1 | P11: 120 | Q11: 209.7 | R11: 172.3 | S11: 193 | T11: 177
A12: Rural+Urban | B12: 2023 | C12: April | D12: 176.12308 | E12: =((D12-D11)/D11)*100 -> 0.45630046 | F12: =_xlfn.TEXTJOIN( ,TRUE,C12,B12) -> April2023 | G12: =ABS(E12) -> 0.45630046 | H12: 173.8 | I12: 209.3 | J12: 169.6 | K12: 178.4 | L12: 174.9 | M12: 176.3 | N12: 155.4 | O12: 173.4 | P12: 121.3 | Q12: 212.9 | R12: 172.9 | S12: 193.5 | T12: 177.9
A13: Rural+Urban | B13: 2023 | C13: May | D13: 177.45385 | E13: =((D13-D12)/D12)*100 -> 0.7555905 | F13: =_xlfn.TEXTJOIN( ,TRUE,C13,B13) -> May2023 | G13: =ABS(E13) -> 0.7555905 | H13: 173.7 | I13: 214.3 | J13: 173.2 | K13: 179.5 | L13: 170 | M13: 172.2 | N13: 161 | O13: 175.6 | P13: 122.7 | Q13: 218 | R13: 173.4 | S13: 194.2 | T13: 179.1
E16: Monthly CPI rate is calculated by ((CPI of the Current month-CPI of the previous month)/CPI of the previous month)*100)
E17: *Calculation is done on Rural+Urban Data
A19: Row Labels | B19: Abs change in inflation | D19: Row Labels | E19: Monthly Inflation Rate%
A20: April2023 | B20: 0.45630046 | D20: February2023 | E20: -0.59318707
A21: August2022 | B21: 0.12796188 | D21: December2022 | E21: -0.58342041
A22: December2022 | B22: 0.58342041 | D22: November2022 | E22: -0.02176468
A23: February2023 | B23: 0.59318707 | D23: March2023 | E23: 0.0043876969
A24: January2023 | B24: 0.40728738 | D24: August2022 | E24: 0.12796188
A25: July2022 | B25: 0.19452673 | D25: July2022 | E25: 0.19452673
A26: June2022 | B26: 1.0408291 | D26: January2023 | E26: 0.40728738
A27: March2023 | B27: 0.0043876969 | D27: April2023 | E27: 0.45630046
A28: May2023 | B28: 0.7555905 | D28: September2022 | E28: 0.51560021
A29: November2022 | B29: 0.02176468 | D29: October2022 | E29: 0.71901442
A30: October2022 | B30: 0.71901442 | D30: May2023 | E30: 0.7555905
A31: September2022 | B31: 0.51560021 | D31: June2022 | E31: 1.0408291
A32: Grand Total | B32: 5.4198705 | D32: Grand Total | E32: 3.0231262
D37: Insight- | E37: June month of 2022 has highest change in inflation and Feb 2023 has the lowest inflation rate in the 12-month analysis
A40: Q3.2 | B40: Absolute change in Inflation in the same 12 month period | E40: =ABS((D13-D2)/D2) -> 0.019894779
B43: Category | D43: Change in Inflation in 12 month
B44: Cereals and products | D44: =ABS((H13-H2)/H2) -> 0.12064516
B45: Meat and fish | D45: =ABS((I13-I2)/I2) -> 0.023245214 | F45: Insight-
B46: Egg | D46: =ABS((J13-J2)/J2) -> 0.014051522 | F46: In Food and Beverages broader category, SPICES in the biggest individual contributor towards inflation
B47: Milk and products | D47: =ABS((K13-K2)/K2) -> 0.082629674
B48: Oils and fats | D48: =ABS((L13-L2)/L2) -> 0.15380786
B49: Fruits | D49: =ABS((M13-M2)/M2) -> 0.01473188
B50: Vegetables | D50: =ABS((N13-N2)/N2) -> 0.11684037
B51: Pulses and products | D51: =ABS((O13-O2)/O2) -> 0.068776628
...

Sheet Ans2
A1: Sector | B1: Year | C1: Month | D1: General index | H1: YEARS | I1: ANNUAL INFLATION RATE
A2: Rural+Urban | B2: 2017 | C2: January | D2: 130.3 | H2: 2017 | I2: =(D3-D2)/D2 -> 0.05295472
A3: Rural+Urban | B3: 2017 | C3: December | D3: 137.2 | H3: 2018 | I3: =(D5-D4)/D4 -> 0.023374726 | M3: YEAR | N3: YEARLY INFLATION
A4: Rural+Urban | B4: 2018 | C4: January | D4: 136.9 | H4: 2019 | I4: =(D7-D6)/D6 -> 0.077363897 | M4: 2017 | N4: 0.05295472
A5: Rural+Urban | B5: 2018 | C5: December | D5: 140.1 | H5: 2020 | I5: =(D9-D8)/D8 -> 0.05792277 | M5: 2018 | N5: 0.023374726
A6: Rural+Urban | B6: 2019 | C6: January | D6: 139.6 | H6: 2021 | I6: =(D11-D10)/D10 -> 0.056579784 | M6: 2019 | N6: 0.077363897
A7: Rural+Urban | B7: 2019 | C7: December | D7: 150.4 | H7: 2022 | I7: =(D13-D12)/D12 -> 0.06035003 | M7: 2020 | N7: 0.05792277
A8: Rural+Urban | B8: 2020 | C8: January | D8: 150.2 | M8: 2021 | N8: 0.056579784
A9: Rural+Urban | B9: 2020 | C9: December | D9: 158.9 | M9: 2022 | N9: 0.06035003
A10: Rural+Urban | B10: 2021 | C10: January | D10: 157.3 | M10: Grand Total | N10: 0.32854593
A11: Rural+Urban | B11: 2021 | C11: December | D11: 166.2
A12: Rural+Urban | B12: 2022 | C12: January | D12: 165.7
A13: Rural+Urban | B13: 2022 | C13: December | D13: 175.7
A14: Rural+Urban | B14: 2023 | C14: January | D14: 176.5
A16: Annual Inflation Rate is Calculated by a formula ((CPI at the end of that year-CPI at the start of that year)/CPI at the start of the year)*100)
A17: Insight | B17: India’s high inflation in 2019 was driven by supply-side food and fuel shocks rather than excess demand,
B18: making it a case of cost-push inflation amid slowing growth

Sheet Ans1
A1: Sector | B1: Rural | C1: Urban | D1: Rural+Urban | E1: Category
A2: Cereals and products | B2: 173.2 | C2: 174.7 | D2: 173.7 | E2: =VLOOKUP(A2,'Broader Category'!A2:B27,2,FALSE) -> Food and Beverages | H2: Row Labels | I2: Rural% | K2: Row Labels | L2: Urban% | N2: FoodCategory | O2: Rural+Urban%
A3: Meat and fish | B3: 211.5 | C3: 219.4 | D3: 214.3 | E3: =VLOOKUP(A3,'Broader Category'!A3:B28,2,FALSE) -> Food and Beverages | H3: Food and Beverages | I3: 0.50918023 | K3: Clothing and Footwear | L3: 0.11392187 | N3: Food and Beverages | O3: 0.49563854
A4: Egg | B4: 171 | C4: 176.7 | D4: 173.2 | E4: =VLOOKUP(A4,'Broader Category'!A4:B29,2,FALSE) -> Food and Beverages | H4: Clothing and Footwear | I4: 0.12667823 | K4: Education | L4: 0.037665108 | N4: Clothing and Footwear | O4: 0.11885528
A5: Milk and products | B5: 179.6 | C5: 179.4 | D5: 179.5 | E5: =VLOOKUP(A5,'Broader Category'!A5:B30,2,FALSE) -> Food and Beverages | H5: Recreation and Personal Care | I5: 0.079732373 | K5: Pan, tobacco and intoxicants | L5: 0.044000086 | N5: Recreation and Personal Care | O5: 0.076572705
A6: Oils and fats | B6: 173.3 | C6: 164.4 | D6: 170 | E6: =VLOOKUP(A6,'Broader Category'!A6:B31,2,FALSE) -> Food and Beverages | H6: Pan, tobacco and intoxicants | I6: 0.044434071 | K6: Energy | L6: 0.039518197 | N6: Housing and Utilities | O6: 0.075369543
A7: Fruits | B7: 169 | C7: 175.8 | D7: 172.2 | E7: =VLOOKUP(A7,'Broader Category'!A7:B32,2,FALSE) -> Food and Beverages | H7: Health | I7: 0.041744465 | K7: Food and Beverages | L7: 0.50315672 | N7: Pan, tobacco and intoxicants | O7: 0.043184943
A8: Vegetables | B8: 148.7 | C8: 185 | D8: 161 | E8: =VLOOKUP(A8,'Broader Category'!A8:B33,2,FALSE) -> Food and Beverages | H8: Energy | I8: 0.040566373 | K8: Health | L8: 0.039259626 | N8: Health | O8: 0.039897731
A9: Pulses and products | B9: 174.9 | C9: 176.9 | D9: 175.6 | E9: =VLOOKUP(A9,'Broader Category'!A9:B34,2,FALSE) -> Food and Beverages | H9: Education | I9: 0.040077354 | K9: Housing and Utilities | L9: 0.074489862 | N9: Energy | O9: 0.039274665
A10: Sugar and Confectionery | B10: 121.9 | C10: 124.2 | D10: 122.7 | E10: =VLOOKUP(A10,'Broader Category'!A10:B35,2,FALSE) -> Food and Beverages | H10: Housing and Utilities | I10: 0.039966213 | K10: Miscellaneous | L10: 0.036975587 | N10: Education | O10: 0.038050017
A11: Spices | B11: 221 | C11: 211.9 | D11: 218 | E11: =VLOOKUP(A11,'Broader Category'!A11:B36,2,FALSE) -> Food and Beverages | H11: Miscellaneous | I11: 0.039899529 | K11: Recreation and Personal Care | L11: 0.076450688 | N11: Miscellaneous | O11: 0.037749227
A12: Non-alcoholic beverages | B12: 178.7 | C12: 165.9 | D12: 173.4 | E12: =VLOOKUP(A12,'Broader Category'!A12:B37,2,FALSE) -> Food and Beverages | H12: Transportation | I12: 0.03772117 | K12: Transportation | L12: 0.034562262 | N12: Transportation | O12: 0.035407356
A13: Prepared meals, snacks, sweets etc. | B13: 191.1 | C13: 197.7 | D13: 194.2 | E13: =VLOOKUP(A13,'Broader Category'!A13:B38,2,FALSE) -> Food and Beverages | H13: Grand Total | I13: 1 | K13: Grand Total | L13: 1 | N13: Grand Total | O13: 1
A14: Food and beverages | B14: 176.8 | C14: 183.1 | D14: 179.1 | E14: =VLOOKUP(A14,'Broader Category'!A14:B39,2,FALSE) -> Food and Beverages
A15: Pan, tobacco and intoxicants | B15: 199.9 | C15: 204.2 | D15: 201 | E15: =VLOOKUP(A15,'Broader Category'!A15:B40,2,FALSE) -> Pan, tobacco and intoxicants
A16: Clothing | B16: 191.2 | C16: 181.3 | D16: 187.3 | E16: =VLOOKUP(A16,'Broader Category'!A16:B41,2,FALSE) -> Clothing and Footwear
